<?xml version="1.0"?>
<robot name="tang">

  <link name="base_link">
    <visual>
      <geometry>
        <mesh filename="package://tang_description/base_link.obj" scale="0.001 0.001 0.001"/>
      </geometry>
    </visual>
  </link>

  <joint name="left_wheel_joint" type="continuous">
    <axis xyz="0 0 1"/>
    <parent link="base_link"/>
    <child link="left_wheel"/>
    <origin xyz="0 0.18 0" rpy="0.0 0.0 0.0"/>
  </joint>

  <link name="left_wheel">
    <visual>
      <geometry>
        <mesh filename="package://tang_description/CuGoV3_Left.obj" scale="0.001 0.001 0.001"/>
      </geometry>
    </visual>
  </link>

  <joint name="right_wheel_joint" type="continuous">
    <axis xyz="0 0 1"/>
    <parent link="base_link"/>
    <child link="right_wheel"/>
    <origin xyz="0 -0.18 0" rpy="0.0 0.0 0.0"/>
  </joint>

  <link name="right_wheel">
    <visual>
      <geometry>
        <mesh filename="package://tang_description/CuGoV3_Right.obj" scale="0.001 0.001 0.001"/>
      </geometry>
    </visual>
  </link>

</robot>